Workbook

Sheet Instructions
A1: FACULTY POINTS ALLOCATION & MONITORING WORKBOOK
A2: Reference: DBM-CHED Joint Circular No. 1, s. 2026 — Enhanced Implementing Guidelines of DBM-CHED Joint Circular No. 3, s. 2022 (Annex A — List of Criteria and Documentary Evidences, pp. 74-101)
A5: HOW THIS WORKBOOK IS ORGANIZED
A6: Dashboard | B6: At-a-glance summary of points earned versus max per KRA, the Academic Rank Reclassification Calculator, status flags, and a chart. Fill in your basic information at the top.
A7: Rank_Tables | B7: Reference tables transcribed from your source document: Table 2.2 (KRA Weights per Faculty Rank), Table 3.1 (Score Bracket to Sub-rank Increment), and Table 3.2 (Faculty Positions/Salary Grades in SUCs).
A8: KRA I - Instruction | B8: Teaching Effectiveness (SET/SEF), Instructional Materials Development, and Research Advising & Mentorship Services. Maximum: 100 points.
A9: KRA II - Research, Innovation and/or Creative Work | B9: Research Outputs Published, Inventions, and Creative Works. Each criterion caps at 100, but the overall KRA is capped at 100 points.
A10: KRA III - Extension Services | B10: Service to the Institution, Service to the Community, Relevance & Quality of Extension Services, plus Criterion D - a Bonus indicator for Administrative Designations. All four criteria feed into the same 100-point cap.
A11: KRA IV - Professional Development | B11: Involvement in Professional Organizations, Continuing Development, Awards and Recognition, plus Criterion D - Additional Points for Newly Appointed/Hired Faculty (prior academic/industry experience). All four criteria feed into the same 100-point cap.
A13: HOW TO USE THIS WORKBOOK
A14: Step 1 | B14: Go to each KRA sheet (tabs at the bottom) and review the list of criteria and point-earning items, drawn directly from Annex A of the Enhanced Implementing Guidelines.
A15: Step 2 | B15: In the 'Qty / Units Claimed' column (yellow cells, blue text), enter the number of times you qualify for each item (e.g., number of textbooks authored, number of conferences attended, or your actual SET/SEF score).
A16: Step 3 | B16: If an item was co-authored, co-invented, or co-created, set 'My % Share (Co-Authorship)' to your certified percentage contribution (per the Annex C-I Certificate of Contribution forms). It defaults to 100% for sole credit - only change it when points must be shared among two or more people.
A17: Step 4 | B17: 'Points Earned' calculates automatically (Points per Unit x Qty x My % Share), and is automatically capped where the guidelines impose an item-level or criterion-level maximum.
A18: Step 5 | B18: Update the 'Evidence Status' dropdown for each line item (Not Started / In Progress / Evidence Complete / Submitted / Verified) to track your documentary evidence readiness.
A19: Step 6 | B19: Use the 'Remarks / Evidence Notes' column to jot down where each piece of evidence is filed, or any clarifying notes.
A20: Step 7 | B20: Check the Dashboard sheet - it automatically pulls your capped totals from every KRA sheet and shows your overall standing against the 400-point maximum (100 per KRA).
A21: Step 8 | B21: On the Dashboard, select your Current Sub-Rank from the dropdown. The Academic Rank Reclassification Calculator automatically applies your rank's KRA weights (Table 2.2), computes your Weighted Composite Score, determines your sub-rank increment (Table 3.1), and shows your Final Awarded Sub-Rank and Salary Grade - including the cross-rank recomputation rule (Section 8.3) if applicable.
A23: IMPORTANT NOTES
A24: Co-authorship / Co-inventorship | B24: Several items require a signed Certificate of Contribution form (Annexes C through I of the Guidelines) to apportion points among co-authors, co-inventors, or co-creators. Keep these on file.
A25: Point Sharing | B25: Use the 'My % Share (Co-Authorship)' column on each KRA sheet to split points for jointly-produced outputs. Example: a 100-point Academic Book with 2 equal co-authors - set Qty=1 and My % Share=50% to correctly credit 50 points to you. If contribution is unequal, use the certified percentage from the Certificate of Contribution form.
A26: Bracketed / Tiered Items | B26: Some items (e.g., income generation, invention patenting stages, administrative designations) list multiple point values for different tiers or stages. Each tier is listed as its own row - enter a quantity only for the row(s) that actually apply to you.
A27: KRA II Cap | B27: Research Outputs Published, Inventions, and Creative Works are each capped at 100 points individually, but your overall KRA II score is capped at 100 points total (not 300).
A28: KRA III Criterion D (Bonus) | B28: Per Section 36 of the Enhanced Guidelines, points for Administrative Designations are 'added on top' of Criteria A+B+C, but KRA III's final total still cannot exceed 100 points - so Criterion D mainly helps you reach the cap faster, it does not push you past it.
A29: KRA IV Criterion D | B29: Per Sections 37 and 44, Additional Points for Newly Appointed/Hired Faculty (prior academic or industry experience before SUC appointment) is one of four criteria (A+B+C+D) that together are capped at 100 points for KRA IV.
A30: Weighted Composite Score | B30: Your rank does NOT depend on the raw 400-point total. Each KRA's percentage score is weighted differently depending on your current rank (Table 2.2) - e.g., an Instructor's Instruction score counts for 60% of the composite, while a Professor's counts for only 30% (Research counts for 40% instead). This weighted score (0-100) is converted into sub-rank increments via Table 3.1 (max 6 per cycle).
A31: Cross-Rank Recomputation (Sec. 8.3) | B31: If your earned sub-rank increments would push you into the next rank category (e.g., Instructor III to Assistant Professor I), the Guidelines require recomputing your weighted score using the NEXT rank's weights. If you still qualify under the new weights, you get the new rank; otherwise, you're capped at the highest sub-rank of your current rank category. The Dashboard calculator performs this automatically.
A32: Automatic Doctorate Sub-Rank | B32: Separately from the point-based calculator, completing your FIRST doctoral degree automatically grants one sub-rank reclassification (Instructor I to Associate Professor IV only) regardless of point totals, per Section 45. The calculator does not apply this automatically - adjust manually if it applies to you.
A33: Verify Against Source | B33: Point values and rank tables were transcribed from your source document (scanned PDF pages 1-130, plus the Table 2.2/3.1/3.2 images you provided). Please verify against your official copy of the Enhanced Guidelines before any formal submission.

Sheet Dashboard
A1: FACULTY POINTS ALLOCATION & MONITORING DASHBOARD
A2: Based on DBM-CHED Joint Circular No. 1, s. 2026 — Enhanced Implementing Guidelines of JC No. 3, s. 2022
A4: Faculty Name:
A5: Current Sub-Rank:
A6: SUC / Campus:
A7: Evaluation Period:
A9: Key Result Area (KRA) | B9: Max Points | C9: Points Earned | D9: % of Max | E9: Status | F9: Remarks
A10: KRA I - INSTRUCTION | B10: 100 | C10: =KRA_I!I39 -> 0 | D10: =C10/B10 -> 0 | E10: =IF(C10>=B10,"Target Met",IF(C10>=B10*0.75,"On Track",IF(C10>=B10*0.5,"Needs Attention","At Risk"))) -> At Risk
A11: KRA II - RESEARCH, INNOVATION AND/OR CREATIVE WORK | B11: 100 | C11: =KRA_II!I56 -> 0 | D11: =C11/B11 -> 0 | E11: =IF(C11>=B11,"Target Met",IF(C11>=B11*0.75,"On Track",IF(C11>=B11*0.5,"Needs Attention","At Risk"))) -> At Risk
A12: KRA III - EXTENSION SERVICES | B12: 100 | C12: =KRA_III!I73 -> 0 | D12: =C12/B12 -> 0 | E12: =IF(C12>=B12,"Target Met",IF(C12>=B12*0.75,"On Track",IF(C12>=B12*0.5,"Needs Attention","At Risk"))) -> At Risk
A13: KRA IV - PROFESSIONAL DEVELOPMENT | B13: 100 | C13: =KRA_IV!I46 -> 0 | D13: =C13/B13 -> 0 | E13: =IF(C13>=B13,"Target Met",IF(C13>=B13*0.75,"On Track",IF(C13>=B13*0.5,"Needs Attention","At Risk"))) -> At Risk
A14: OVERALL TOTAL (out of 400, unweighted) | B14: =SUM(B10:B13) -> 400 | C14: =SUM(C10:C13) -> 0 | D14: =C14/B14 -> 0
A16: ACADEMIC RANK RECLASSIFICATION CALCULATOR (Tables 2.2, 3.1 & 3.2)
A17: Select your Current Sub-Rank above. This calculator applies your rank's KRA weights (Table 2.2) to your KRA scores above to compute a Weighted Composite Score (0-100), converts it to sub-rank increments (Table 3.1), and applies the cross-rank recomputation rule (Section 8.3) if the increments would cross into the next rank category. See the Rank_Tables sheet for the full reference tables.
A19: Current Sub-Rank Index (1-19) | E19: =IFERROR(MATCH(B5,Rank_Tables!$C$26:$C$44,0),1) -> 1
A20: Current Rank Category | E20: =IFERROR(INDEX(Rank_Tables!$B$26:$B$44,E19),"") -> Instructor
A21: Current Salary Grade | E21: =IFERROR(INDEX(Rank_Tables!$D$26:$D$44,E19),"") -> SG-12
A22: Applicable Weight - Instruction | E22: =IFERROR(VLOOKUP(E20,Rank_Tables!$A$6:$F$10,3,FALSE()),0) -> 0.6
A23: Applicable Weight - Research, Innovation and/or Creative Work | E23: =IFERROR(VLOOKUP(E20,Rank_Tables!$A$6:$F$10,4,FALSE()),0) -> 0.1
A24: Applicable Weight - Extension | E24: =IFERROR(VLOOKUP(E20,Rank_Tables!$A$6:$F$10,5,FALSE()),0) -> 0.2
A25: Applicable Weight - Professional Development | E25: =IFERROR(VLOOKUP(E20,Rank_Tables!$A$6:$F$10,6,FALSE()),0) -> 0.1
A26: WEIGHTED COMPOSITE SCORE (0-100) | E26: =C10*E22+C11*E23+C12*E24+C13*E25 -> 0
A27: Sub-rank Increment Earned (Table 3.1) | E27: =IFERROR(VLOOKUP(E26,Rank_Tables!$A$15:$C$21,3,TRUE()),0) -> 0
A28: Tentative New Sub-Rank Index | E28: =MIN(E19+E27,19) -> 1
A29: Tentative New Rank Category | E29: =IFERROR(INDEX(Rank_Tables!$B$26:$B$44,E28),"") -> Instructor
A30: Crosses into a New Rank Category? | E30: =IF(E29<>E20,"YES - recompute with new rank weights (Sec. 8.3)","No") -> No
A31: [If crossed] Re-computed Weight - Instruction | E31: =IFERROR(VLOOKUP(E29,Rank_Tables!$A$6:$F$10,3,FALSE()),0) -> 0.6
A32: [If crossed] Re-computed Weight - Research | E32: =IFERROR(VLOOKUP(E29,Rank_Tables!$A$6:$F$10,4,FALSE()),0) -> 0.1
A33: [If crossed] Re-computed Weight - Extension | E33: =IFERROR(VLOOKUP(E29,Rank_Tables!$A$6:$F$10,5,FALSE()),0) -> 0.2
A34: [If crossed] Re-computed Weight - Professional Development | E34: =IFERROR(VLOOKUP(E29,Rank_Tables!$A$6:$F$10,6,FALSE()),0) -> 0.1
A35: [If crossed] Re-computed Weighted Score | E35: =C10*E31+C11*E32+C12*E33+C13*E34 -> 0
A36: [If crossed] Re-computed Sub-rank Increment | E36: =IFERROR(VLOOKUP(E35,Rank_Tables!$A$15:$C$21,3,TRUE()),0) -> 0
A37: [If crossed] Re-computed New Index | E37: =MIN(E19+E36,19) -> 1
A38: [If crossed] Re-computed New Category | E38: =IFERROR(INDEX(Rank_Tables!$B$26:$B$44,E37),"") -> Instructor
A39: Highest Sub-rank Index of CURRENT Rank Category | E39: =IFERROR(VLOOKUP(E20,Rank_Tables!$A$49:$C$53,3,FALSE()),E19) -> 3
A40: FINAL AWARDED SUB-RANK INDEX | E40: =IF(E30="No",E28,IF(E38=E29,E37,E39)) -> 1
A41: FINAL AWARDED SUB-RANK | E41: =IFERROR(INDEX(Rank_Tables!$C$26:$C$44,E40),"") -> Instructor I
A42: Corresponding Salary Grade | E42: =IFERROR(INDEX(Rank_Tables!$D$26:$D$44,E40),"") -> SG-12
A43: Number of Sub-ranks Gained This Cycle | E43: =MAX(E40-E19,0) -> 0
A45: Reminder (Section 45, Enhanced Guidelines): A faculty member from Instructor I to Associate Professor IV is automatically granted ONE sub-rank reclassification upon completing their FIRST doctoral degree within the evaluation period (vertically aligned with their master's field, from an eligible HEI) - regardless of the computed score above. This does not apply to Associate Professor V or any Professor rank. This calculator does not automatically apply this rule - adjust manually if applicable.
...

Sheet Rank_Tables
A1: ACADEMIC RANK REFERENCE TABLES
A2: Source: Tables 2.2, 3.1, and 3.2 of the DBM-CHED Joint Circular / Enhanced Implementing Guidelines
A4: Table 2.2 - KRA Weights per Faculty Rank
A5: Rank Category | B5: Applicable Sub-ranks | C5: Instruction | D5: Research, Innovation and/or Creative Work | E5: Extension | F5: Professional Development
A6: Instructor | B6: I - III | C6: 0.6 | D6: 0.1 | E6: 0.2 | F6: 0.1
A7: Assistant Professor | B7: I - IV | C7: 0.5 | D7: 0.2 | E7: 0.2 | F7: 0.1
A8: Associate Professor | B8: I - V | C8: 0.4 | D8: 0.3 | E8: 0.2 | F8: 0.1
A9: Professor | B9: I - VI | C9: 0.3 | D9: 0.4 | E9: 0.2 | F9: 0.1
A10: College/University Professor | B10: (single rank) | C10: 0.2 | D10: 0.5 | E10: 0.2 | F10: 0.1
A13: Table 3.1 - Score Bracket and Corresponding Number of Sub-rank Increment
A14: Min Score | B14: Max Score | C14: No. of Sub-rank Increment
A15: 0 | B15: 40 | C15: 0
A16: 41 | B16: 50 | C16: 1
A17: 51 | B17: 60 | C17: 2
A18: 61 | B18: 70 | C18: 3
A19: 71 | B19: 80 | C19: 4
A20: 81 | B20: 90 | C20: 5
A21: 91 | B21: 100 | C21: 6
A24: Table 3.2 - Faculty Positions in SUCs
A25: # | B25: Rank Category | C25: Sub-rank | D25: Salary Grade
A26: 1 | B26: Instructor | C26: Instructor I | D26: SG-12
A27: 2 | B27: Instructor | C27: Instructor II | D27: SG-13
A28: 3 | B28: Instructor | C28: Instructor III | D28: SG-14
A29: 4 | B29: Assistant Professor | C29: Assistant Professor I | D29: SG-15
A30: 5 | B30: Assistant Professor | C30: Assistant Professor II | D30: SG-16
A31: 6 | B31: Assistant Professor | C31: Assistant Professor III | D31: SG-17
A32: 7 | B32: Assistant Professor | C32: Assistant Professor IV | D32: SG-18
A33: 8 | B33: Associate Professor | C33: Associate Professor I | D33: SG-19
A34: 9 | B34: Associate Professor | C34: Associate Professor II | D34: SG-20
A35: 10 | B35: Associate Professor | C35: Associate Professor III | D35: SG-21
A36: 11 | B36: Associate Professor | C36: Associate Professor IV | D36: SG-22
A37: 12 | B37: Associate Professor | C37: Associate Professor V | D37: SG-23
... A44: 19 | B44: College/University Professor | C44: College/University Professor | D44: SG-30
A47: Helper - Rank Category Index Range (for cross-rank logic)
A48: Rank Category | B48: Min Index (#) | C48: Max Index (#)
A49: Instructor | B49: 1 | C49: 3
A50: Assistant Professor | B50: 4 | C50: 7
A51: Associate Professor | B51: 8 | C51: 12
A52: Professor | B52: 13 | C52: 18
A53: College/University Professor | B53: 19 | C53: 19
...

Sheet KRA_I
A1: KRA I - INSTRUCTION (KRA Maximum: 100 points)
A2: For items with multiple authors/co-inventors/co-creators, set 'My % Share' to your certified percentage contribution (Annex C-I Certificate of Contribution). Defaults to 100% (sole credit).
A4: No. | B4: Criterion / Category | C4: Item / Criteria | D4: Points per Unit | E4: Unit | F4: Item/Sub-Cap Max | G4: Qty / Units Claimed | H4: My % Share (Co-Authorship) | I4: Points Earned | J4: Evidence Status | K4: Remarks / Evidence Notes
B5: Criterion A - Teaching Effectiveness | F5: 60
A6: 1 | C6: Student Evaluation of Teachers (SET) - rating-based score | D6: 36 | E6: score (max 36) | G6: 0 | H6: 1 | I6: =D6*G6*H6 -> 0 | J6: Not Started
A7: 2 | C7: Supervisor's Evaluation of Faculty (SEF) - rating-based score | D7: 24 | E7: score (max 24) | G7: 0 | H7: 1 | I7: =D7*G7*H7 -> 0 | J7: Not Started
I8: =SUM(I6:I7) -> 0
I9: =MIN(I8,60) -> 0
B10: Note: For faculty with special status (official study leave, maternity leave, sabbatical leave, newly appointed, teaching in SUC laboratory schools), see Section 10 of the Enhanced Guidelines for applicable conditions/adjustments.
B12: Criterion B - Instructional Materials Development | F12: 30
A13: 3 | C13: Sole Author of a Textbook (per textbook) | D13: 30 | E13: per item | G13: 0 | H13: 1 | I13: =D13*G13*H13 -> 0 | J13: Not Started
A14: 4 | C14: Sole Author of a Module (per module) | D14: 16 | E14: per item | G14: 0 | H14: 1 | I14: =D14*G14*H14 -> 0 | J14: Not Started
A15: 5 | C15: Sole Author of an Instructional Manual (per manual) | D15: 16 | E15: per item | G15: 0 | H15: 1 | I15: =D15*G15*H15 -> 0 | J15: Not Started
A16: 6 | C16: Sole Author of Multimedia Teaching Materials (per material) | D16: 16 | E16: per item | G16: 0 | H16: 1 | I16: =D16*G16*H16 -> 0 | J16: Not Started
A17: 7 | C17: Academic Program Developed/Revised & Implemented - Lead | D17: 10 | E17: per program | G17: 0 | H17: 1 | I17: =D17*G17*H17 -> 0 | J17: Not Started
A18: 8 | C18: Academic Program Developed/Revised & Implemented - Contributor | D18: 5 | E18: per program | G18: 0 | H18: 1 | I18: =D18*G18*H18 -> 0 | J18: Not Started
I19: =SUM(I13:I18) -> 0
I20: =MIN(I19,30) -> 0
B21: Note: For co-authored works, points are shared per Annex C - Certificate of Contribution Form_IM (Section 12/13).
B23: Criterion C - Research Advising and Mentorship Services | F23: 10
A24: 9 | C24: Adviser - Special/Capstone Project (SP/CP) | D24: 3 | E24: per student/group | G24: 0 | H24: 1 | I24: =D24*G24*H24 -> 0 | J24: Not Started
A25: 10 | C25: Adviser - Undergraduate Thesis (UT) | D25: 5 | E25: per student/group | G25: 0 | H25: 1 | I25: =D25*G25*H25 -> 0 | J25: Not Started
A26: 11 | C26: Adviser - Master's Thesis (MT) | D26: 8 | E26: per student/group | G26: 0 | H26: 1 | I26: =D26*G26*H26 -> 0 | J26: Not Started
A27: 12 | C27: Adviser - Doctoral Dissertation (DD) | D27: 10 | E27: per student/group | G27: 0 | H27: 1 | I27: =D27*G27*H27 -> 0 | J27: Not Started
A28: 13 | C28: Panel Member - Special/Capstone Project (SP/CP) | D28: 1 | E28: per student/group | G28: 0 | H28: 1 | I28: =D28*G28*H28 -> 0 | J28: Not Started
A29: 14 | C29: Panel Member - Undergraduate Thesis (UT) | D29: 1 | E29: per student/group | G29: 0 | H29: 1 | I29: =D29*G29*H29 -> 0 | J29: Not Started
A30: 15 | C30: Panel Member - Master's Thesis (MT) | D30: 2 | E30: per student/group | G30: 0 | H30: 1 | I30: =D30*G30*H30 -> 0 | J30: Not Started
A31: 16 | C31: Panel Member - Doctoral Dissertation (DD) | D31: 2 | E31: per student/group | G31: 0 | H31: 1 | I31: =D31*G31*H31 -> 0 | J31: Not Started
A32: 17 | C32: Mentorship Services (coach/mentor to student or group) | D32: 3 | E32: per student/group | G32: 0 | H32: 1 | I32: =D32*G32*H32 -> 0 | J32: Not Started
I33: =SUM(I24:I32) -> 0
I34: =MIN(I33,10) -> 0
B35: Note: See Section 15 of the Enhanced Guidelines for applicable conditions.
I38: =I9+I20+I34 -> 0
I39: =MIN(I38,100) -> 0

Sheet KRA_II
A1: KRA II - RESEARCH, INNOVATION AND/OR CREATIVE WORK (KRA Maximum: 100 points)
A2: For items with multiple authors/co-inventors/co-creators, set 'My % Share' to your certified percentage contribution (Annex C-I Certificate of Contribution). Defaults to 100% (sole credit).
A4: No. | B4: Criterion / Category | C4: Item / Criteria | D4: Points per Unit | E4: Unit | F4: Item/Sub-Cap Max | G4: Qty / Units Claimed | H4: My % Share (Co-Authorship) | I4: Points Earned | J4: Evidence Status | K4: Remarks / Evidence Notes
B5: Criterion A - Research Outputs Published | F5: 100
A6: 1 | C6: Sole Author of an Academic Book | D6: 100 | E6: per book | G6: 0 | H6: 1 | I6: =D6*G6*H6 -> 0 | J6: Not Started
A7: 2 | C7: Sole Author of Edited Academic Book Chapter | D7: 35 | E7: per chapter | G7: 0 | H7: 1 | I7: =D7*G7*H7 -> 0 | J7: Not Started
A8: 3 | C8: Sole Author of a Journal Article (indexed in Scopus/WoS/ACI) | D8: 50 | E8: per article | G8: 0 | H8: 1 | I8: =D8*G8*H8 -> 0 | J8: Not Started
A9: 4 | C9: Sole Author of an Academic Monograph | D9: 100 | E9: per monograph | G9: 0 | H9: 1 | I9: =D9*G9*H9 -> 0 | J9: Not Started
A10: 5 | C10: Research Output Translated into Project, Policy, or Product | D10: 35 | E10: per output (max 70) | G10: 0 | H10: 1 | I10: =D10*G10*H10 -> 0 | J10: Not Started
A11: 6 | C11: Research Publication Cited by another indexed publication | D11: 10 | E11: per citation (max 60) | G11: 0 | H11: 1 | I11: =D11*G11*H11 -> 0 | J11: Not Started
I12: =SUM(I6:I11) -> 0
I13: =MIN(I12,100) -> 0
B14: Note: See Sections 18-21 of the Enhanced Guidelines. Journal article points reflect base rate; verify tiering in Section 19. Co-authorship uses Annex D - Certificate of Contribution Form_Research Output.
B16: Criterion B - Inventions | F16: 100
A17: 7 | C17: Invention Patent - Acceptance Stage | D17: 10 | E17: per invention | G17: 0 | H17: 1 | I17: =D17*G17*H17 -> 0 | J17: Not Started
A18: 8 | C18: Invention Patent - Publication Stage | D18: 20 | E18: per invention | G18: 0 | H18: 1 | I18: =D18*G18*H18 -> 0 | J18: Not Started
A19: 9 | C19: Invention Patent - Grant Stage | D19: 80 | E19: per invention | G19: 0 | H19: 1 | I19: =D19*G19*H19 -> 0 | J19: Not Started
A20: 10 | C20: Commercialized Patented Product - Local | D20: 5 | E20: per product (max 20) | G20: 0 | H20: 1 | I20: =MIN(D20*G20*H20,F20) -> 0 | J20: Not Started
A21: 11 | C21: Commercialized Patented Product - International | D21: 10 | E21: per product (max 30) | G21: 0 | H21: 1 | I21: =MIN(D21*G21*H21,F21) -> 0 | J21: Not Started
A22: 12 | C22: Utility Model (registered) | D22: 10 | E22: per item | G22: 0 | H22: 1 | I22: =D22*G22*H22 -> 0 | J22: Not Started
A23: 13 | C23: Industrial Design (registered) | D23: 5 | E23: per item | G23: 0 | H23: 1 | I23: =D23*G23*H23 -> 0 | J23: Not Started
A24: 14 | C24: Copyrighted & Utilized Software Product - New | D24: 10 | E24: per product | G24: 0 | H24: 1 | I24: =D24*G24*H24 -> 0 | J24: Not Started
A25: 15 | C25: Copyrighted & Utilized Software Product - Updated | D25: 4 | E25: per product | G25: 0 | H25: 1 | I25: =D25*G25*H25 -> 0 | J25: Not Started
A26: 16 | C26: New Plant Variety / Animal Breed / Microbial Strain Developed | D26: 10 | E26: per item | G26: 0 | H26: 1 | I26: =D26*G26*H26 -> 0 | J26: Not Started
I27: =SUM(I17:I26) -> 0
I28: =MIN(I27,100) -> 0
B29: Note: See Sections 23-24 of the Enhanced Guidelines. Co-inventorship uses Annex F/G/H Certificate of Contribution forms.
B31: Criterion C - Creative Works | F31: 100
A32: 17 | C32: Musical Composition (orchestra/band/chamber/ensemble/choral) | D32: 20 | E32: per work | G32: 0 | H32: 1 | I32: =D32*G32*H32 -> 0 | J32: Not Started
A33: 18 | C33: Musical Arrangement | D33: 20 | E33: per work | G33: 0 | H33: 1 | I33: =D33*G33*H33 -> 0 | J33: Not Started
A34: 19 | C34: Musical Performance (vocal or instrumental) | D34: 10 | E34: per performance | G34: 0 | H34: 1 | I34: =D34*G34*H34 -> 0 | J34: Not Started
A35: 20 | C35: Conducting | D35: 10 | E35: per performance | G35: 0 | H35: 1 | I35: =D35*G35*H35 -> 0 | J35: Not Started
A36: 21 | C36: Music Production (original work produced) | D36: 20 | E36: per work | G36: 0 | H36: 1 | I36: =D36*G36*H36 -> 0 | J36: Not Started
A37: 22 | C37: Original Choreography (Dance) | D37: 20 | E37: per work | G37: 0 | H37: 1 | I37: =D37*G37*H37 -> 0 | J37: Not Started
A38: 23 | C38: Dance Performance | D38: 10 | E38: per performance | G38: 0 | H38: 1 | I38: =D38*G38*H38 -> 0 | J38: Not Started
A39: 24 | C39: Playwright (Theatre) | D39: 20 | E39: per work | G39: 0 | H39: 1 | I39: =D39*G39*H39 -> 0 | J39: Not Started
A40: 25 | C40: Directing (Theatre) | D40: 20 | E40: per production | G40: 0 | H40: 1 | I40: =D40*G40*H40 -> 0 | J40: Not Started
A41: 26 | C41: Acting (Theatre) | D41: 20 | E41: per production | G41: 0 | H41: 1 | I41: =D41*G41*H41 -> 0 | J41: Not Started
A42: 27 | C42: Production Design (Theatre) | D42: 20 | E42: per production | G42: 0 | H42: 1 | I42: =D42*G42*H42 -> 0 | J42: Not Started
A43: 28 | C43: Visual Arts - Painting/Drawing/Mixed Media/Sculpture/Photography/Digital Art | D43: 20 | E43: per exhibited work | G43: 0 | H43: 1 | I43: =D43*G43*H43 -> 0 | J43: Not Started
...

Sheet KRA_III
A1: KRA III - EXTENSION SERVICES (KRA Maximum: 100 points)
A2: For items with multiple authors/co-inventors/co-creators, set 'My % Share' to your certified percentage contribution (Annex C-I Certificate of Contribution). Defaults to 100% (sole credit).
A4: No. | B4: Criterion / Category | C4: Item / Criteria | D4: Points per Unit | E4: Unit | F4: Item/Sub-Cap Max | G4: Qty / Units Claimed | H4: My % Share (Co-Authorship) | I4: Points Earned | J4: Evidence Status | K4: Remarks / Evidence Notes
B5: Criterion A - Service to the Institution | F5: 30
A6: 1 | C6: Successful Linkage/Networking/Partnership Activity | D6: 5 | E6: per activity | G6: 0 | H6: 1 | I6: =D6*G6*H6 -> 0 | J6: Not Started
A7: 2 | C7: Income Generation (Lead) - Php 100,000 and below | D7: 2 | E7: per project | G7: 0 | H7: 1 | I7: =D7*G7*H7 -> 0 | J7: Not Started
A8: 3 | C8: Income Generation (Lead) - Php 100,001 to 500,000 | D8: 4 | E8: per project | G8: 0 | H8: 1 | I8: =D8*G8*H8 -> 0 | J8: Not Started
A9: 4 | C9: Income Generation (Lead) - Php 500,001 to 6,000,000 | D9: 6 | E9: per project | G9: 0 | H9: 1 | I9: =D9*G9*H9 -> 0 | J9: Not Started
A10: 5 | C10: Income Generation (Lead) - Php 6,000,001 to 12,000,000 | D10: 12 | E10: per project | G10: 0 | H10: 1 | I10: =D10*G10*H10 -> 0 | J10: Not Started
A11: 6 | C11: Income Generation (Lead) - Above Php 12,000,000 | D11: 18 | E11: per project | G11: 0 | H11: 1 | I11: =D11*G11*H11 -> 0 | J11: Not Started
A12: 7 | C12: Income Generation (Contributor) - Php 100,000 and below | D12: 1 | E12: per project | G12: 0 | H12: 1 | I12: =D12*G12*H12 -> 0 | J12: Not Started
A13: 8 | C13: Income Generation (Contributor) - Php 100,001 to 500,000 | D13: 2 | E13: per project | G13: 0 | H13: 1 | I13: =D13*G13*H13 -> 0 | J13: Not Started
A14: 9 | C14: Income Generation (Contributor) - Php 500,001 to 6,000,000 | D14: 3 | E14: per project | G14: 0 | H14: 1 | I14: =D14*G14*H14 -> 0 | J14: Not Started
A15: 10 | C15: Income Generation (Contributor) - Php 6,000,001 to 12,000,000 | D15: 6 | E15: per project | G15: 0 | H15: 1 | I15: =D15*G15*H15 -> 0 | J15: Not Started
A16: 11 | C16: Income Generation (Contributor) - Above Php 12,000,000 | D16: 9 | E16: per project | G16: 0 | H16: 1 | I16: =D16*G16*H16 -> 0 | J16: Not Started
I17: =SUM(I6:I16) -> 0
I18: =MIN(I17,30) -> 0
B19: Note: See Sections 29-31 of the Enhanced Guidelines. Income sources: commercialization, grants from external funding agencies, industry-based projects.
B21: Criterion B - Service to the Community | F21: 50
A22: 12 | C22: Accreditation/Evaluation/Assessment/QA Activities - Local | D22: 8 | E22: per engagement | G22: 0 | H22: 1 | I22: =D22*G22*H22 -> 0 | J22: Not Started
A23: 13 | C23: Accreditation/Evaluation/Assessment/QA Activities - International | D23: 10 | E23: per engagement | G23: 0 | H23: 1 | I23: =D23*G23*H23 -> 0 | J23: Not Started
A24: 14 | C24: Judge/Examiner - Research Awards | D24: 2 | E24: per engagement | G24: 0 | H24: 1 | I24: =D24*G24*H24 -> 0 | J24: Not Started
A25: 15 | C25: Judge/Examiner - Academic Competitions | D25: 1 | E25: per engagement | G25: 0 | H25: 1 | I25: =D25*G25*H25 -> 0 | J25: Not Started
A26: 16 | C26: Short-term Consultant/Expert - Local | D26: 8 | E26: per engagement | G26: 0 | H26: 1 | I26: =D26*G26*H26 -> 0 | J26: Not Started
A27: 17 | C27: Short-term Consultant/Expert - International | D27: 10 | E27: per engagement | G27: 0 | H27: 1 | I27: =D27*G27*H27 -> 0 | J27: Not Started
A28: 18 | C28: Writer of Occasional Newspaper Column | D28: 2 | E28: per article (max 10) | G28: 0 | H28: 1 | I28: =D28*G28*H28 -> 0 | J28: Not Started
A29: 19 | C29: Writer of Regular Newspaper Column | D29: 10 | E29: per engagement | G29: 0 | H29: 1 | I29: =D29*G29*H29 -> 0 | J29: Not Started
A30: 20 | C30: Host of TV/Radio Program | D30: 10 | E30: per engagement | G30: 0 | H30: 1 | I30: =D30*G30*H30 -> 0 | J30: Not Started
A31: 21 | C31: Guesting as Technical Expert (TV/radio/print/online media) | D31: 1 | E31: per engagement (max 10) | G31: 0 | H31: 1 | I31: =D31*G31*H31 -> 0 | J31: Not Started
A32: 22 | C32: Resource Person/Facilitator/Moderator/Plenary Speaker/Panelist - Local (per hour) | D32: 2 | E32: per hour | G32: 0 | H32: 1 | I32: =D32*G32*H32 -> 0 | J32: Not Started
A33: 23 | C33: Resource Person/Facilitator/Moderator/Plenary Speaker/Panelist - International (per hour) | D33: 3 | E33: per hour | G33: 0 | H33: 1 | I33: =D33*G33*H33 -> 0 | J33: Not Started
... A35: 25 | C35: Institutional Social Responsibility - Extension Project (Participant) | D35: 2 | E35: per activity (max 30) | G35: 0 | H35: 1 | I35: =D35*G35*H35 -> 0 | J35: Not Started
I36: =SUM(I22:I35) -> 0
I37: =MIN(I36,50) -> 0
B38: Note: See Sections 33-34 of the Enhanced Guidelines.
B40: Criterion C - Relevance and Quality of Extension Services | F40: 20
A41: 26 | C41: Client Satisfaction Rating for Extension Projects | D41: 20 | E41: rating-based score | F41: 20 | G41: 0 | H41: 1 | I41: =MIN(D41*G41*H41,F41) -> 0 | J41: Not Started
I42: =SUM(I41:I41) -> 0
I43: =MIN(I42,20) -> 0
B44: Note: See Section 35 of the Enhanced Guidelines. The extension project must also be declared under Institutional Social Responsibility (Criterion B) to be credited here.
...

Sheet KRA_IV
A1: KRA IV - PROFESSIONAL DEVELOPMENT (KRA Maximum: 100 points)
A2: For items with multiple authors/co-inventors/co-creators, set 'My % Share' to your certified percentage contribution (Annex C-I Certificate of Contribution). Defaults to 100% (sole credit).
A4: No. | B4: Criterion / Category | C4: Item / Criteria | D4: Points per Unit | E4: Unit | F4: Item/Sub-Cap Max | G4: Qty / Units Claimed | H4: My % Share (Co-Authorship) | I4: Points Earned | J4: Evidence Status | K4: Remarks / Evidence Notes
B5: Criterion A - Involvement in Professional Organizations | F5: 20
A6: 1 | C6: Membership & Participation in Registered Professional Organizations/Societies | D6: 5 | E6: per organization | G6: 0 | H6: 1 | I6: =D6*G6*H6 -> 0 | J6: Not Started
I7: =SUM(I6:I6) -> 0
I8: =MIN(I7,20) -> 0
B9: Note: See Section 38 of the Enhanced Guidelines.
B11: Criterion B - Continuing Development | F11: 60
A12: 2 | C12: Post-Master's Diploma or Certificate | D12: 10 | E12: per credential | G12: 0 | H12: 1 | I12: =D12*G12*H12 -> 0 | J12: Not Started
A13: 3 | C13: Post-Doctorate Diploma or Certificate | D13: 10 | E13: per credential | G13: 0 | H13: 1 | I13: =D13*G13*H13 -> 0 | J13: Not Started
A14: 4 | C14: Additional Master's Degree | D14: 20 | E14: per degree | G14: 0 | H14: 1 | I14: =D14*G14*H14 -> 0 | J14: Not Started
A15: 5 | C15: Doctorate Degree or Additional Doctorate Degree | D15: 40 | E15: per degree | G15: 0 | H15: 1 | I15: =D15*G15*H15 -> 0 | J15: Not Started
A16: 6 | C16: Attendance in Conferences/Seminars/Workshops/Industry Immersion - Local | D16: 1 | E16: per activity (max 10) | G16: 0 | H16: 1 | I16: =D16*G16*H16 -> 0 | J16: Not Started
A17: 7 | C17: Attendance in Conferences/Seminars/Workshops/Industry Immersion - International | D17: 2 | E17: per activity (max 10) | G17: 0 | H17: 1 | I17: =D17*G17*H17 -> 0 | J17: Not Started
A18: 8 | C18: Paper Presentation in Conferences - Local | D18: 3 | E18: per presentation (max 10) | G18: 0 | H18: 1 | I18: =D18*G18*H18 -> 0 | J18: Not Started
A19: 9 | C19: Paper Presentation in Conferences - International | D19: 5 | E19: per presentation (max 10) | G19: 0 | H19: 1 | I19: =D19*G19*H19 -> 0 | J19: Not Started
I20: =SUM(I12:I19) -> 0
I21: =MIN(I20,60) -> 0
B22: Note: See Sections 39-42 of the Enhanced Guidelines.
B24: Criterion C - Awards and Recognition | F24: 20
A25: 10 | C25: Award of Distinction - Institutional | D25: 2 | E25: per award | G25: 0 | H25: 1 | I25: =D25*G25*H25 -> 0 | J25: Not Started
A26: 11 | C26: Award of Distinction - Local and Regional (City/Municipality/Province) | D26: 3 | E26: per award | G26: 0 | H26: 1 | I26: =D26*G26*H26 -> 0 | J26: Not Started
A27: 12 | C27: Award of Distinction - National | D27: 4 | E27: per award | G27: 0 | H27: 1 | I27: =D27*G27*H27 -> 0 | J27: Not Started
I28: =SUM(I25:I27) -> 0
I29: =MIN(I28,20) -> 0
B30: Note: See Section 43 of the Enhanced Guidelines.
B32: Criterion D - Additional Points for Newly Appointed/Hired Faculty | F32: 20
A33: 13 | C33: Prior Academic Experience (before SUC appointment) - as President | D33: 5 | E33: per year | G33: 0 | H33: 1 | I33: =D33*G33*H33 -> 0 | J33: Not Started
A34: 14 | C34: Prior Academic Experience (before SUC appointment) - as VP/Dean/Director | D34: 4 | E34: per year | G34: 0 | H34: 1 | I34: =D34*G34*H34 -> 0 | J34: Not Started
A35: 15 | C35: Prior Academic Experience (before SUC appointment) - as Department/Program Head | D35: 3 | E35: per year | G35: 0 | H35: 1 | I35: =D35*G35*H35 -> 0 | J35: Not Started
A36: 16 | C36: Prior Academic Experience (before SUC appointment) - as Faculty Member | D36: 2 | E36: per year | G36: 0 | H36: 1 | I36: =D36*G36*H36 -> 0 | J36: Not Started
A37: 17 | C37: Prior Industry Experience (non-academic, before SUC appointment) - Managerial/Supervisory | D37: 4 | E37: per year | G37: 0 | H37: 1 | I37: =D37*G37*H37 -> 0 | J37: Not Started
A38: 18 | C38: Prior Industry Experience (non-academic, before SUC appointment) - Technical and Skilled | D38: 3 | E38: per year | G38: 0 | H38: 1 | I38: =D38*G38*H38 -> 0 | J38: Not Started
A39: 19 | C39: Prior Industry Experience (non-academic, before SUC appointment) - Support/Administrative Staff | D39: 2 | E39: per year | G39: 0 | H39: 1 | I39: =D39*G39*H39 -> 0 | J39: Not Started
I40: =SUM(I33:I39) -> 0
I41: =MIN(I40,20) -> 0
B42: Note: See Section 44 of the Enhanced Guidelines. Applies to newly appointed/hired faculty previously employed in private HEIs, industry, or an SUC under contract of service, teaching full-time, prior to their SUC appointment.
I45: =I8+I21+I29+I41 -> 0
I46: =MIN(I45,100) -> 0
